ERROR:django.request:Internal Server Error: /users/1323232
Traceback (most recent call last):
  File "/home/andrushens/anime/ISPLabs/lab3-4/my_site/venv/lib/python3.8/site-packages/django/core/handlers/exception.py", line 47, in inner
    response = get_response(request)
  File "/home/andrushens/anime/ISPLabs/lab3-4/my_site/venv/lib/python3.8/site-packages/django/core/handlers/base.py", line 181, in _get_response
    response = wrapped_callback(request, *callback_args, **callback_kwargs)
  File "/home/andrushens/anime/ISPLabs/lab3-4/my_site/venv/lib/python3.8/site-packages/django/views/generic/base.py", line 70, in view
    return self.dispatch(request, *args, **kwargs)
  File "/home/andrushens/anime/ISPLabs/lab3-4/my_site/venv/lib/python3.8/site-packages/django/views/generic/base.py", line 98, in dispatch
    return handler(request, *args, **kwargs)
  File "/home/andrushens/anime/ISPLabs/lab3-4/my_site/main/views.py", line 176, in get
    if (Account.objects.get(user_id=pk) is not None):
  File "/home/andrushens/anime/ISPLabs/lab3-4/my_site/venv/lib/python3.8/site-packages/django/db/models/manager.py", line 85, in manager_method
    return getattr(self.get_queryset(), name)(*args, **kwargs)
  File "/home/andrushens/anime/ISPLabs/lab3-4/my_site/venv/lib/python3.8/site-packages/django/db/models/query.py", line 435, in get
    raise self.model.DoesNotExist(
main.models.Account.DoesNotExist: Account matching query does not exist.
ERROR:django.request:Internal Server Error: /users/1323232
Traceback (most recent call last):
  File "/home/andrushens/anime/ISPLabs/lab3-4/my_site/venv/lib/python3.8/site-packages/django/core/handlers/exception.py", line 47, in inner
    response = get_response(request)
  File "/home/andrushens/anime/ISPLabs/lab3-4/my_site/venv/lib/python3.8/site-packages/django/core/handlers/base.py", line 181, in _get_response
    response = wrapped_callback(request, *callback_args, **callback_kwargs)
  File "/home/andrushens/anime/ISPLabs/lab3-4/my_site/venv/lib/python3.8/site-packages/django/views/generic/base.py", line 70, in view
    return self.dispatch(request, *args, **kwargs)
  File "/home/andrushens/anime/ISPLabs/lab3-4/my_site/venv/lib/python3.8/site-packages/django/views/generic/base.py", line 98, in dispatch
    return handler(request, *args, **kwargs)
  File "/home/andrushens/anime/ISPLabs/lab3-4/my_site/main/views.py", line 176, in get
    if (Account.objects.get(user_id=pk) is not None):
  File "/home/andrushens/anime/ISPLabs/lab3-4/my_site/venv/lib/python3.8/site-packages/django/db/models/manager.py", line 85, in manager_method
    return getattr(self.get_queryset(), name)(*args, **kwargs)
  File "/home/andrushens/anime/ISPLabs/lab3-4/my_site/venv/lib/python3.8/site-packages/django/db/models/query.py", line 435, in get
    raise self.model.DoesNotExist(
main.models.Account.DoesNotExist: Account matching query does not exist.
ERROR:django.request:Internal Server Error: /users/1323
Traceback (most recent call last):
  File "/home/andrushens/anime/ISPLabs/lab3-4/my_site/venv/lib/python3.8/site-packages/django/core/handlers/exception.py", line 47, in inner
    response = get_response(request)
  File "/home/andrushens/anime/ISPLabs/lab3-4/my_site/venv/lib/python3.8/site-packages/django/core/handlers/base.py", line 181, in _get_response
    response = wrapped_callback(request, *callback_args, **callback_kwargs)
  File "/home/andrushens/anime/ISPLabs/lab3-4/my_site/venv/lib/python3.8/site-packages/django/views/generic/base.py", line 70, in view
    return self.dispatch(request, *args, **kwargs)
  File "/home/andrushens/anime/ISPLabs/lab3-4/my_site/venv/lib/python3.8/site-packages/django/views/generic/base.py", line 98, in dispatch
    return handler(request, *args, **kwargs)
  File "/home/andrushens/anime/ISPLabs/lab3-4/my_site/main/views.py", line 176, in get
    if (Account.objects.get(user_id=pk) is not None):
  File "/home/andrushens/anime/ISPLabs/lab3-4/my_site/venv/lib/python3.8/site-packages/django/db/models/manager.py", line 85, in manager_method
    return getattr(self.get_queryset(), name)(*args, **kwargs)
  File "/home/andrushens/anime/ISPLabs/lab3-4/my_site/venv/lib/python3.8/site-packages/django/db/models/query.py", line 435, in get
    raise self.model.DoesNotExist(
main.models.Account.DoesNotExist: Account matching query does not exist.
ERROR:django.request:Internal Server Error: /users/13
Traceback (most recent call last):
  File "/home/andrushens/anime/ISPLabs/lab3-4/my_site/venv/lib/python3.8/site-packages/django/core/handlers/exception.py", line 47, in inner
    response = get_response(request)
  File "/home/andrushens/anime/ISPLabs/lab3-4/my_site/venv/lib/python3.8/site-packages/django/core/handlers/base.py", line 181, in _get_response
    response = wrapped_callback(request, *callback_args, **callback_kwargs)
  File "/home/andrushens/anime/ISPLabs/lab3-4/my_site/venv/lib/python3.8/site-packages/django/views/generic/base.py", line 70, in view
    return self.dispatch(request, *args, **kwargs)
  File "/home/andrushens/anime/ISPLabs/lab3-4/my_site/venv/lib/python3.8/site-packages/django/views/generic/base.py", line 98, in dispatch
    return handler(request, *args, **kwargs)
  File "/home/andrushens/anime/ISPLabs/lab3-4/my_site/main/views.py", line 176, in get
    if (Account.objects.get(user_id=pk) is not None):
  File "/home/andrushens/anime/ISPLabs/lab3-4/my_site/venv/lib/python3.8/site-packages/django/db/models/manager.py", line 85, in manager_method
    return getattr(self.get_queryset(), name)(*args, **kwargs)
  File "/home/andrushens/anime/ISPLabs/lab3-4/my_site/venv/lib/python3.8/site-packages/django/db/models/query.py", line 435, in get
    raise self.model.DoesNotExist(
main.models.Account.DoesNotExist: Account matching query does not exist.
WARNING:django.request:Not Found: /userWQWQ
INFO:django.utils.autoreload:/home/andrushens/anime/ISPLabs/lab3-4/my_site/main/views.py changed, reloading.
DEBUG:asyncio:Using selector: EpollSelector
WARNING:django.request:Not Found: /userWQWQ
WARNING:django.request:Not Found: /users/1ewqeqw
ERROR:django.request:Internal Server Error: /users/12333
Traceback (most recent call last):
  File "/home/andrushens/anime/ISPLabs/lab3-4/my_site/venv/lib/python3.8/site-packages/django/core/handlers/exception.py", line 47, in inner
    response = get_response(request)
  File "/home/andrushens/anime/ISPLabs/lab3-4/my_site/venv/lib/python3.8/site-packages/django/core/handlers/base.py", line 181, in _get_response
    response = wrapped_callback(request, *callback_args, **callback_kwargs)
  File "/home/andrushens/anime/ISPLabs/lab3-4/my_site/venv/lib/python3.8/site-packages/django/views/generic/base.py", line 70, in view
    return self.dispatch(request, *args, **kwargs)
  File "/home/andrushens/anime/ISPLabs/lab3-4/my_site/venv/lib/python3.8/site-packages/django/views/generic/base.py", line 98, in dispatch
    return handler(request, *args, **kwargs)
  File "/home/andrushens/anime/ISPLabs/lab3-4/my_site/main/views.py", line 176, in get
    if (Account.objects.get(user_id=pk) is not None):
  File "/home/andrushens/anime/ISPLabs/lab3-4/my_site/venv/lib/python3.8/site-packages/django/db/models/manager.py", line 85, in manager_method
    return getattr(self.get_queryset(), name)(*args, **kwargs)
  File "/home/andrushens/anime/ISPLabs/lab3-4/my_site/venv/lib/python3.8/site-packages/django/db/models/query.py", line 435, in get
    raise self.model.DoesNotExist(
main.models.Account.DoesNotExist: Account matching query does not exist.
INFO:django.utils.autoreload:/home/andrushens/anime/ISPLabs/lab3-4/my_site/main/views.py changed, reloading.
DEBUG:asyncio:Using selector: EpollSelector
INFO:django.utils.autoreload:/home/andrushens/anime/ISPLabs/lab3-4/my_site/main/views.py changed, reloading.
DEBUG:asyncio:Using selector: EpollSelector
INFO:django.utils.autoreload:/home/andrushens/anime/ISPLabs/lab3-4/my_site/main/views.py changed, reloading.
DEBUG:asyncio:Using selector: EpollSelector
ERROR:django.request:Internal Server Error: /users/12333
Traceback (most recent call last):
  File "/home/andrushens/anime/ISPLabs/lab3-4/my_site/venv/lib/python3.8/site-packages/django/core/handlers/exception.py", line 47, in inner
    response = get_response(request)
  File "/home/andrushens/anime/ISPLabs/lab3-4/my_site/venv/lib/python3.8/site-packages/django/core/handlers/base.py", line 181, in _get_response
    response = wrapped_callback(request, *callback_args, **callback_kwargs)
  File "/home/andrushens/anime/ISPLabs/lab3-4/my_site/venv/lib/python3.8/site-packages/django/views/generic/base.py", line 70, in view
    return self.dispatch(request, *args, **kwargs)
  File "/home/andrushens/anime/ISPLabs/lab3-4/my_site/venv/lib/python3.8/site-packages/django/views/generic/base.py", line 98, in dispatch
    return handler(request, *args, **kwargs)
  File "/home/andrushens/anime/ISPLabs/lab3-4/my_site/main/views.py", line 176, in get
    if (Account.objects.get(user_id=pk) is not None):
  File "/home/andrushens/anime/ISPLabs/lab3-4/my_site/venv/lib/python3.8/site-packages/django/db/models/manager.py", line 85, in manager_method
    return getattr(self.get_queryset(), name)(*args, **kwargs)
  File "/home/andrushens/anime/ISPLabs/lab3-4/my_site/venv/lib/python3.8/site-packages/django/db/models/query.py", line 435, in get
    raise self.model.DoesNotExist(
main.models.Account.DoesNotExist: Account matching query does not exist.
INFO:django.utils.autoreload:/home/andrushens/anime/ISPLabs/lab3-4/my_site/main/views.py changed, reloading.
DEBUG:asyncio:Using selector: EpollSelector
ERROR:django.request:Internal Server Error: /users/12333
Traceback (most recent call last):
  File "/home/andrushens/anime/ISPLabs/lab3-4/my_site/venv/lib/python3.8/site-packages/django/core/handlers/exception.py", line 47, in inner
    response = get_response(request)
  File "/home/andrushens/anime/ISPLabs/lab3-4/my_site/venv/lib/python3.8/site-packages/django/core/handlers/base.py", line 181, in _get_response
    response = wrapped_callback(request, *callback_args, **callback_kwargs)
  File "/home/andrushens/anime/ISPLabs/lab3-4/my_site/venv/lib/python3.8/site-packages/django/views/generic/base.py", line 70, in view
    return self.dispatch(request, *args, **kwargs)
  File "/home/andrushens/anime/ISPLabs/lab3-4/my_site/venv/lib/python3.8/site-packages/django/views/generic/base.py", line 98, in dispatch
    return handler(request, *args, **kwargs)
  File "/home/andrushens/anime/ISPLabs/lab3-4/my_site/main/views.py", line 176, in get
    if (Account.objects.get(user_id=pk) is not None):
  File "/home/andrushens/anime/ISPLabs/lab3-4/my_site/venv/lib/python3.8/site-packages/django/db/models/manager.py", line 85, in manager_method
    return getattr(self.get_queryset(), name)(*args, **kwargs)
  File "/home/andrushens/anime/ISPLabs/lab3-4/my_site/venv/lib/python3.8/site-packages/django/db/models/query.py", line 435, in get
    raise self.model.DoesNotExist(
main.models.Account.DoesNotExist: Account matching query does not exist.
INFO:django.utils.autoreload:/home/andrushens/anime/ISPLabs/lab3-4/my_site/main/views.py changed, reloading.
DEBUG:asyncio:Using selector: EpollSelector
INFO:django.utils.autoreload:/home/andrushens/anime/ISPLabs/lab3-4/my_site/main/views.py changed, reloading.
DEBUG:asyncio:Using selector: EpollSelector
ERROR:main.views:tur ffffffffffffffffff
ERROR:django.request:Internal Server Error: /users/12333
Traceback (most recent call last):
  File "/home/andrushens/anime/ISPLabs/lab3-4/my_site/venv/lib/python3.8/site-packages/django/core/handlers/exception.py", line 47, in inner
    response = get_response(request)
  File "/home/andrushens/anime/ISPLabs/lab3-4/my_site/venv/lib/python3.8/site-packages/django/core/handlers/base.py", line 181, in _get_response
    response = wrapped_callback(request, *callback_args, **callback_kwargs)
  File "/home/andrushens/anime/ISPLabs/lab3-4/my_site/venv/lib/python3.8/site-packages/django/views/generic/base.py", line 70, in view
    return self.dispatch(request, *args, **kwargs)
  File "/home/andrushens/anime/ISPLabs/lab3-4/my_site/venv/lib/python3.8/site-packages/django/views/generic/base.py", line 98, in dispatch
    return handler(request, *args, **kwargs)
  File "/home/andrushens/anime/ISPLabs/lab3-4/my_site/main/views.py", line 179, in get
    if (Account.objects.get(user_id=pk) is not None):
  File "/home/andrushens/anime/ISPLabs/lab3-4/my_site/venv/lib/python3.8/site-packages/django/db/models/manager.py", line 85, in manager_method
    return getattr(self.get_queryset(), name)(*args, **kwargs)
  File "/home/andrushens/anime/ISPLabs/lab3-4/my_site/venv/lib/python3.8/site-packages/django/db/models/query.py", line 435, in get
    raise self.model.DoesNotExist(
main.models.Account.DoesNotExist: Account matching query does not exist.
ERROR:main.views:tur ffffffffffffffffff
ERROR:django.request:Internal Server Error: /users/12333
Traceback (most recent call last):
  File "/home/andrushens/anime/ISPLabs/lab3-4/my_site/venv/lib/python3.8/site-packages/django/core/handlers/exception.py", line 47, in inner
    response = get_response(request)
  File "/home/andrushens/anime/ISPLabs/lab3-4/my_site/venv/lib/python3.8/site-packages/django/core/handlers/base.py", line 181, in _get_response
    response = wrapped_callback(request, *callback_args, **callback_kwargs)
  File "/home/andrushens/anime/ISPLabs/lab3-4/my_site/venv/lib/python3.8/site-packages/django/views/generic/base.py", line 70, in view
    return self.dispatch(request, *args, **kwargs)
  File "/home/andrushens/anime/ISPLabs/lab3-4/my_site/venv/lib/python3.8/site-packages/django/views/generic/base.py", line 98, in dispatch
    return handler(request, *args, **kwargs)
  File "/home/andrushens/anime/ISPLabs/lab3-4/my_site/main/views.py", line 179, in get
    if (Account.objects.get(user_id=pk) is not None):
  File "/home/andrushens/anime/ISPLabs/lab3-4/my_site/venv/lib/python3.8/site-packages/django/db/models/manager.py", line 85, in manager_method
    return getattr(self.get_queryset(), name)(*args, **kwargs)
  File "/home/andrushens/anime/ISPLabs/lab3-4/my_site/venv/lib/python3.8/site-packages/django/db/models/query.py", line 435, in get
    raise self.model.DoesNotExist(
main.models.Account.DoesNotExist: Account matching query does not exist.
INFO:django.utils.autoreload:/home/andrushens/anime/ISPLabs/lab3-4/my_site/main/views.py changed, reloading.
DEBUG:asyncio:Using selector: EpollSelector
ERROR:main.views:tur ffffffffffffffffff
ERROR:django.request:Internal Server Error: /users/12333
Traceback (most recent call last):
  File "/home/andrushens/anime/ISPLabs/lab3-4/my_site/venv/lib/python3.8/site-packages/django/core/handlers/exception.py", line 47, in inner
    response = get_response(request)
  File "/home/andrushens/anime/ISPLabs/lab3-4/my_site/venv/lib/python3.8/site-packages/django/core/handlers/base.py", line 181, in _get_response
    response = wrapped_callback(request, *callback_args, **callback_kwargs)
  File "/home/andrushens/anime/ISPLabs/lab3-4/my_site/venv/lib/python3.8/site-packages/django/views/generic/base.py", line 70, in view
    return self.dispatch(request, *args, **kwargs)
  File "/home/andrushens/anime/ISPLabs/lab3-4/my_site/venv/lib/python3.8/site-packages/django/views/generic/base.py", line 98, in dispatch
    return handler(request, *args, **kwargs)
  File "/home/andrushens/anime/ISPLabs/lab3-4/my_site/main/views.py", line 177, in get
    reviews = Review.objects.get('author').filter(author_id=pk)
  File "/home/andrushens/anime/ISPLabs/lab3-4/my_site/venv/lib/python3.8/site-packages/django/db/models/manager.py", line 85, in manager_method
    return getattr(self.get_queryset(), name)(*args, **kwargs)
  File "/home/andrushens/anime/ISPLabs/lab3-4/my_site/venv/lib/python3.8/site-packages/django/db/models/query.py", line 424, in get
    clone = self._chain() if self.query.combinator else self.filter(*args, **kwargs)
  File "/home/andrushens/anime/ISPLabs/lab3-4/my_site/venv/lib/python3.8/site-packages/django/db/models/query.py", line 941, in filter
    return self._filter_or_exclude(False, args, kwargs)
  File "/home/andrushens/anime/ISPLabs/lab3-4/my_site/venv/lib/python3.8/site-packages/django/db/models/query.py", line 961, in _filter_or_exclude
    clone._filter_or_exclude_inplace(negate, args, kwargs)
  File "/home/andrushens/anime/ISPLabs/lab3-4/my_site/venv/lib/python3.8/site-packages/django/db/models/query.py", line 968, in _filter_or_exclude_inplace
    self._query.add_q(Q(*args, **kwargs))
  File "/home/andrushens/anime/ISPLabs/lab3-4/my_site/venv/lib/python3.8/site-packages/django/db/models/sql/query.py", line 1393, in add_q
    clause, _ = self._add_q(q_object, self.used_aliases)
  File "/home/andrushens/anime/ISPLabs/lab3-4/my_site/venv/lib/python3.8/site-packages/django/db/models/sql/query.py", line 1412, in _add_q
    child_clause, needed_inner = self.build_filter(
  File "/home/andrushens/anime/ISPLabs/lab3-4/my_site/venv/lib/python3.8/site-packages/django/db/models/sql/query.py", line 1283, in build_filter
    arg, value = filter_expr
ValueError: too many values to unpack (expected 2)
ERROR:main.views:tur ffffffffffffffffff
ERROR:django.request:Internal Server Error: /users/12333
Traceback (most recent call last):
  File "/home/andrushens/anime/ISPLabs/lab3-4/my_site/venv/lib/python3.8/site-packages/django/core/handlers/exception.py", line 47, in inner
    response = get_response(request)
  File "/home/andrushens/anime/ISPLabs/lab3-4/my_site/venv/lib/python3.8/site-packages/django/core/handlers/base.py", line 181, in _get_response
    response = wrapped_callback(request, *callback_args, **callback_kwargs)
  File "/home/andrushens/anime/ISPLabs/lab3-4/my_site/venv/lib/python3.8/site-packages/django/views/generic/base.py", line 70, in view
    return self.dispatch(request, *args, **kwargs)
  File "/home/andrushens/anime/ISPLabs/lab3-4/my_site/venv/lib/python3.8/site-packages/django/views/generic/base.py", line 98, in dispatch
    return handler(request, *args, **kwargs)
  File "/home/andrushens/anime/ISPLabs/lab3-4/my_site/main/views.py", line 177, in get
    reviews = Review.objects.get('author').filter(author_id=pk)
  File "/home/andrushens/anime/ISPLabs/lab3-4/my_site/venv/lib/python3.8/site-packages/django/db/models/manager.py", line 85, in manager_method
    return getattr(self.get_queryset(), name)(*args, **kwargs)
  File "/home/andrushens/anime/ISPLabs/lab3-4/my_site/venv/lib/python3.8/site-packages/django/db/models/query.py", line 424, in get
    clone = self._chain() if self.query.combinator else self.filter(*args, **kwargs)
  File "/home/andrushens/anime/ISPLabs/lab3-4/my_site/venv/lib/python3.8/site-packages/django/db/models/query.py", line 941, in filter
    return self._filter_or_exclude(False, args, kwargs)
  File "/home/andrushens/anime/ISPLabs/lab3-4/my_site/venv/lib/python3.8/site-packages/django/db/models/query.py", line 961, in _filter_or_exclude
    clone._filter_or_exclude_inplace(negate, args, kwargs)
  File "/home/andrushens/anime/ISPLabs/lab3-4/my_site/venv/lib/python3.8/site-packages/django/db/models/query.py", line 968, in _filter_or_exclude_inplace
    self._query.add_q(Q(*args, **kwargs))
  File "/home/andrushens/anime/ISPLabs/lab3-4/my_site/venv/lib/python3.8/site-packages/django/db/models/sql/query.py", line 1393, in add_q
    clause, _ = self._add_q(q_object, self.used_aliases)
  File "/home/andrushens/anime/ISPLabs/lab3-4/my_site/venv/lib/python3.8/site-packages/django/db/models/sql/query.py", line 1412, in _add_q
    child_clause, needed_inner = self.build_filter(
  File "/home/andrushens/anime/ISPLabs/lab3-4/my_site/venv/lib/python3.8/site-packages/django/db/models/sql/query.py", line 1283, in build_filter
    arg, value = filter_expr
ValueError: too many values to unpack (expected 2)
INFO:django.utils.autoreload:/home/andrushens/anime/ISPLabs/lab3-4/my_site/main/views.py changed, reloading.
DEBUG:asyncio:Using selector: EpollSelector
INFO:django.utils.autoreload:/home/andrushens/anime/ISPLabs/lab3-4/my_site/main/views.py changed, reloading.
DEBUG:asyncio:Using selector: EpollSelector
INFO:django.utils.autoreload:/home/andrushens/anime/ISPLabs/lab3-4/my_site/main/views.py changed, reloading.
DEBUG:asyncio:Using selector: EpollSelector
ERROR:django.request:Internal Server Error: /users/12333
Traceback (most recent call last):
  File "/home/andrushens/anime/ISPLabs/lab3-4/my_site/venv/lib/python3.8/site-packages/django/core/handlers/exception.py", line 47, in inner
    response = get_response(request)
  File "/home/andrushens/anime/ISPLabs/lab3-4/my_site/venv/lib/python3.8/site-packages/django/core/handlers/base.py", line 181, in _get_response
    response = wrapped_callback(request, *callback_args, **callback_kwargs)
  File "/home/andrushens/anime/ISPLabs/lab3-4/my_site/venv/lib/python3.8/site-packages/django/views/generic/base.py", line 70, in view
    return self.dispatch(request, *args, **kwargs)
  File "/home/andrushens/anime/ISPLabs/lab3-4/my_site/venv/lib/python3.8/site-packages/django/views/generic/base.py", line 98, in dispatch
    return handler(request, *args, **kwargs)
  File "/home/andrushens/anime/ISPLabs/lab3-4/my_site/main/views.py", line 174, in get
    reviews = Review.objects.get('author').filter(author_id=pk)
  File "/home/andrushens/anime/ISPLabs/lab3-4/my_site/venv/lib/python3.8/site-packages/django/db/models/manager.py", line 85, in manager_method
    return getattr(self.get_queryset(), name)(*args, **kwargs)
  File "/home/andrushens/anime/ISPLabs/lab3-4/my_site/venv/lib/python3.8/site-packages/django/db/models/query.py", line 424, in get
    clone = self._chain() if self.query.combinator else self.filter(*args, **kwargs)
  File "/home/andrushens/anime/ISPLabs/lab3-4/my_site/venv/lib/python3.8/site-packages/django/db/models/query.py", line 941, in filter
    return self._filter_or_exclude(False, args, kwargs)
  File "/home/andrushens/anime/ISPLabs/lab3-4/my_site/venv/lib/python3.8/site-packages/django/db/models/query.py", line 961, in _filter_or_exclude
    clone._filter_or_exclude_inplace(negate, args, kwargs)
  File "/home/andrushens/anime/ISPLabs/lab3-4/my_site/venv/lib/python3.8/site-packages/django/db/models/query.py", line 968, in _filter_or_exclude_inplace
    self._query.add_q(Q(*args, **kwargs))
  File "/home/andrushens/anime/ISPLabs/lab3-4/my_site/venv/lib/python3.8/site-packages/django/db/models/sql/query.py", line 1393, in add_q
    clause, _ = self._add_q(q_object, self.used_aliases)
  File "/home/andrushens/anime/ISPLabs/lab3-4/my_site/venv/lib/python3.8/site-packages/django/db/models/sql/query.py", line 1412, in _add_q
    child_clause, needed_inner = self.build_filter(
  File "/home/andrushens/anime/ISPLabs/lab3-4/my_site/venv/lib/python3.8/site-packages/django/db/models/sql/query.py", line 1283, in build_filter
    arg, value = filter_expr
ValueError: too many values to unpack (expected 2)
WARNING:django.request:Not Found: /usersr
WARNING:django.request:Not Found: /users
ERROR:django.request:Internal Server Error: /users/1
Traceback (most recent call last):
  File "/home/andrushens/anime/ISPLabs/lab3-4/my_site/venv/lib/python3.8/site-packages/django/core/handlers/exception.py", line 47, in inner
    response = get_response(request)
  File "/home/andrushens/anime/ISPLabs/lab3-4/my_site/venv/lib/python3.8/site-packages/django/core/handlers/base.py", line 181, in _get_response
    response = wrapped_callback(request, *callback_args, **callback_kwargs)
  File "/home/andrushens/anime/ISPLabs/lab3-4/my_site/venv/lib/python3.8/site-packages/django/views/generic/base.py", line 70, in view
    return self.dispatch(request, *args, **kwargs)
  File "/home/andrushens/anime/ISPLabs/lab3-4/my_site/venv/lib/python3.8/site-packages/django/views/generic/base.py", line 98, in dispatch
    return handler(request, *args, **kwargs)
  File "/home/andrushens/anime/ISPLabs/lab3-4/my_site/main/views.py", line 174, in get
    reviews = Review.objects.get('author').filter(author_id=pk)
  File "/home/andrushens/anime/ISPLabs/lab3-4/my_site/venv/lib/python3.8/site-packages/django/db/models/manager.py", line 85, in manager_method
    return getattr(self.get_queryset(), name)(*args, **kwargs)
  File "/home/andrushens/anime/ISPLabs/lab3-4/my_site/venv/lib/python3.8/site-packages/django/db/models/query.py", line 424, in get
    clone = self._chain() if self.query.combinator else self.filter(*args, **kwargs)
  File "/home/andrushens/anime/ISPLabs/lab3-4/my_site/venv/lib/python3.8/site-packages/django/db/models/query.py", line 941, in filter
    return self._filter_or_exclude(False, args, kwargs)
  File "/home/andrushens/anime/ISPLabs/lab3-4/my_site/venv/lib/python3.8/site-packages/django/db/models/query.py", line 961, in _filter_or_exclude
    clone._filter_or_exclude_inplace(negate, args, kwargs)
  File "/home/andrushens/anime/ISPLabs/lab3-4/my_site/venv/lib/python3.8/site-packages/django/db/models/query.py", line 968, in _filter_or_exclude_inplace
    self._query.add_q(Q(*args, **kwargs))
  File "/home/andrushens/anime/ISPLabs/lab3-4/my_site/venv/lib/python3.8/site-packages/django/db/models/sql/query.py", line 1393, in add_q
    clause, _ = self._add_q(q_object, self.used_aliases)
  File "/home/andrushens/anime/ISPLabs/lab3-4/my_site/venv/lib/python3.8/site-packages/django/db/models/sql/query.py", line 1412, in _add_q
    child_clause, needed_inner = self.build_filter(
  File "/home/andrushens/anime/ISPLabs/lab3-4/my_site/venv/lib/python3.8/site-packages/django/db/models/sql/query.py", line 1283, in build_filter
    arg, value = filter_expr
ValueError: too many values to unpack (expected 2)
INFO:django.utils.autoreload:/home/andrushens/anime/ISPLabs/lab3-4/my_site/main/views.py changed, reloading.
DEBUG:asyncio:Using selector: EpollSelector
WARNING:django.request:Not Found: /static/style.css
WARNING:django.request:Not Found: /static/style.css
ERROR:django.request:Internal Server Error: /users/1
Traceback (most recent call last):
  File "/home/andrushens/anime/ISPLabs/lab3-4/my_site/venv/lib/python3.8/site-packages/django/core/handlers/exception.py", line 47, in inner
    response = get_response(request)
  File "/home/andrushens/anime/ISPLabs/lab3-4/my_site/venv/lib/python3.8/site-packages/django/core/handlers/base.py", line 181, in _get_response
    response = wrapped_callback(request, *callback_args, **callback_kwargs)
  File "/home/andrushens/anime/ISPLabs/lab3-4/my_site/venv/lib/python3.8/site-packages/django/views/generic/base.py", line 70, in view
    return self.dispatch(request, *args, **kwargs)
  File "/home/andrushens/anime/ISPLabs/lab3-4/my_site/venv/lib/python3.8/site-packages/django/views/generic/base.py", line 98, in dispatch
    return handler(request, *args, **kwargs)
  File "/home/andrushens/anime/ISPLabs/lab3-4/my_site/main/views.py", line 174, in get
    reviews = Review.objects.get('author').filter(author_id=pk)
  File "/home/andrushens/anime/ISPLabs/lab3-4/my_site/venv/lib/python3.8/site-packages/django/db/models/manager.py", line 85, in manager_method
    return getattr(self.get_queryset(), name)(*args, **kwargs)
  File "/home/andrushens/anime/ISPLabs/lab3-4/my_site/venv/lib/python3.8/site-packages/django/db/models/query.py", line 424, in get
    clone = self._chain() if self.query.combinator else self.filter(*args, **kwargs)
  File "/home/andrushens/anime/ISPLabs/lab3-4/my_site/venv/lib/python3.8/site-packages/django/db/models/query.py", line 941, in filter
    return self._filter_or_exclude(False, args, kwargs)
  File "/home/andrushens/anime/ISPLabs/lab3-4/my_site/venv/lib/python3.8/site-packages/django/db/models/query.py", line 961, in _filter_or_exclude
    clone._filter_or_exclude_inplace(negate, args, kwargs)
  File "/home/andrushens/anime/ISPLabs/lab3-4/my_site/venv/lib/python3.8/site-packages/django/db/models/query.py", line 968, in _filter_or_exclude_inplace
    self._query.add_q(Q(*args, **kwargs))
  File "/home/andrushens/anime/ISPLabs/lab3-4/my_site/venv/lib/python3.8/site-packages/django/db/models/sql/query.py", line 1393, in add_q
    clause, _ = self._add_q(q_object, self.used_aliases)
  File "/home/andrushens/anime/ISPLabs/lab3-4/my_site/venv/lib/python3.8/site-packages/django/db/models/sql/query.py", line 1412, in _add_q
    child_clause, needed_inner = self.build_filter(
  File "/home/andrushens/anime/ISPLabs/lab3-4/my_site/venv/lib/python3.8/site-packages/django/db/models/sql/query.py", line 1283, in build_filter
    arg, value = filter_expr
ValueError: too many values to unpack (expected 2)
INFO:django.utils.autoreload:/home/andrushens/anime/ISPLabs/lab3-4/my_site/main/views.py changed, reloading.
DEBUG:asyncio:Using selector: EpollSelector
INFO:django.utils.autoreload:/home/andrushens/anime/ISPLabs/lab3-4/my_site/main/views.py changed, reloading.
DEBUG:asyncio:Using selector: EpollSelector
WARNING:django.request:Not Found: /static/style.css
ERROR:django.request:Internal Server Error: /users/11111
Traceback (most recent call last):
  File "/home/andrushens/anime/ISPLabs/lab3-4/my_site/venv/lib/python3.8/site-packages/django/core/handlers/exception.py", line 47, in inner
    response = get_response(request)
  File "/home/andrushens/anime/ISPLabs/lab3-4/my_site/venv/lib/python3.8/site-packages/django/core/handlers/base.py", line 181, in _get_response
    response = wrapped_callback(request, *callback_args, **callback_kwargs)
  File "/home/andrushens/anime/ISPLabs/lab3-4/my_site/venv/lib/python3.8/site-packages/django/views/generic/base.py", line 70, in view
    return self.dispatch(request, *args, **kwargs)
  File "/home/andrushens/anime/ISPLabs/lab3-4/my_site/venv/lib/python3.8/site-packages/django/views/generic/base.py", line 98, in dispatch
    return handler(request, *args, **kwargs)
  File "/home/andrushens/anime/ISPLabs/lab3-4/my_site/main/views.py", line 176, in get
    if (Account.objects.get(user_id=pk) is not None):
  File "/home/andrushens/anime/ISPLabs/lab3-4/my_site/venv/lib/python3.8/site-packages/django/db/models/manager.py", line 85, in manager_method
    return getattr(self.get_queryset(), name)(*args, **kwargs)
  File "/home/andrushens/anime/ISPLabs/lab3-4/my_site/venv/lib/python3.8/site-packages/django/db/models/query.py", line 435, in get
    raise self.model.DoesNotExist(
main.models.Account.DoesNotExist: Account matching query does not exist.
WARNING:django.request:Not Found: /static/style.css
WARNING:django.request:Not Found: /static/style.css
WARNING:django.request:Not Found: /static/admin/css/fonts.css
WARNING:django.request:Not Found: /static/admin/css/dashboard.css
WARNING:django.request:Not Found: /static/admin/css/fonts.css
WARNING:django.request:Not Found: /static/admin/img/icon-addlink.svg
WARNING:django.request:Not Found: /static/admin/img/icon-changelink.svg
WARNING:django.request:Not Found: /static/admin/img/icon-deletelink.svg
WARNING:django.request:Not Found: /static/admin/js/vendor/jquery/jquery.min.js
WARNING:django.request:Not Found: /static/admin/js/jquery.init.js
WARNING:django.request:Not Found: /static/admin/js/vendor/xregexp/xregexp.min.js
WARNING:django.request:Not Found: /static/admin/css/fonts.css
WARNING:django.request:Not Found: /static/admin/js/vendor/jquery/jquery.min.js
WARNING:django.request:Not Found: /static/admin/js/jquery.init.js
WARNING:django.request:Not Found: /static/admin/js/vendor/xregexp/xregexp.min.js
WARNING:django.request:Not Found: /static/admin/img/icon-addlink.svg
WARNING:django.request:Not Found: /static/admin/img/tooltag-add.svg
WARNING:django.request:Not Found: /static/admin/js/jquery.init.js
WARNING:django.request:Not Found: /static/admin/js/vendor/jquery/jquery.min.js
WARNING:django.request:Not Found: /static/admin/js/vendor/xregexp/xregexp.min.js
WARNING:django.request:Not Found: /static/admin/css/fonts.css
WARNING:django.request:Not Found: /static/admin/img/search.svg
WARNING:django.request:Not Found: /static/admin/js/vendor/jquery/jquery.min.js
WARNING:django.request:Not Found: /static/admin/js/jquery.init.js
WARNING:django.request:Not Found: /static/admin/img/icon-yes.svg
WARNING:django.request:Not Found: /static/admin/js/vendor/xregexp/xregexp.min.js
WARNING:django.request:Not Found: /static/admin/img/icon-addlink.svg
WARNING:django.request:Not Found: /static/admin/img/tooltag-add.svg
WARNING:django.request:Not Found: /static/admin/js/vendor/jquery/jquery.min.js
WARNING:django.request:Not Found: /static/admin/js/jquery.init.js
WARNING:django.request:Not Found: /static/admin/js/vendor/xregexp/xregexp.min.js
WARNING:django.request:Not Found: /static/admin/css/fonts.css
WARNING:django.request:Not Found: /static/admin/js/jquery.init.js
WARNING:django.request:Not Found: /static/admin/js/vendor/xregexp/xregexp.min.js
WARNING:django.request:Not Found: /static/admin/img/icon-addlink.svg
WARNING:django.request:Not Found: /static/admin/css/fonts.css
WARNING:django.request:Not Found: /static/admin/img/icon-yes.svg
DEBUG:asyncio:Using selector: EpollSelector
DEBUG:asyncio:Using selector: EpollSelector
WARNING:django.request:Not Found: /static/admin/css/fonts.css
WARNING:django.request:Not Found: /static/style.css
WARNING:django.request:Not Found: /static/style.css
INFO:main.views:root logged in
WARNING:django.request:Not Found: /static/style.css
WARNING:django.request:Not Found: /static/style.css
INFO:main.views:root created review tilte1
WARNING:django.request:Not Found: /static/style.css
WARNING:django.request:Not Found: /static/style.css
WARNING:django.request:Not Found: /static/style.css
INFO:main.views:root created review qwertas
WARNING:django.request:Not Found: /static/style.css
WARNING:django.request:Not Found: /static/style.css
ERROR:main.views:root caused error on creating review
WARNING:django.request:Not Found: /static/style.css
ERROR:main.views:root caused error on creating review
WARNING:django.request:Not Found: /static/style.css
WARNING:django.request:Not Found: /static/style.css
WARNING:django.request:Not Found: /static/admin/css/dashboard.css
WARNING:django.request:Not Found: /static/admin/css/fonts.css
WARNING:django.request:Not Found: /static/admin/img/icon-addlink.svg
WARNING:django.request:Not Found: /static/admin/img/icon-changelink.svg
INFO:main.views:root logged out
WARNING:django.request:Not Found: /static/style.css
WARNING:django.request:Not Found: /static/style.css
INFO:main.views:pudge registered
WARNING:django.request:Not Found: /static/style.css
INFO:main.views:pudge logged in
WARNING:django.request:Not Found: /static/style.css
WARNING:django.request:Not Found: /static/style.css
ERROR:django.request:Internal Server Error: /reviews/tilte1q
Traceback (most recent call last):
  File "/home/andrushens/anime/ISPLabs/lab3-4/my_site/venv/lib/python3.8/site-packages/django/core/handlers/exception.py", line 47, in inner
    response = get_response(request)
  File "/home/andrushens/anime/ISPLabs/lab3-4/my_site/venv/lib/python3.8/site-packages/django/core/handlers/base.py", line 181, in _get_response
    response = wrapped_callback(request, *callback_args, **callback_kwargs)
  File "/home/andrushens/anime/ISPLabs/lab3-4/my_site/venv/lib/python3.8/site-packages/django/views/generic/base.py", line 70, in view
    return self.dispatch(request, *args, **kwargs)
  File "/home/andrushens/anime/ISPLabs/lab3-4/my_site/venv/lib/python3.8/site-packages/django/views/generic/base.py", line 98, in dispatch
    return handler(request, *args, **kwargs)
  File "/home/andrushens/anime/ISPLabs/lab3-4/my_site/main/views.py", line 166, in get
    review = Review.objects.get(slug=slug)
  File "/home/andrushens/anime/ISPLabs/lab3-4/my_site/venv/lib/python3.8/site-packages/django/db/models/manager.py", line 85, in manager_method
    return getattr(self.get_queryset(), name)(*args, **kwargs)
  File "/home/andrushens/anime/ISPLabs/lab3-4/my_site/venv/lib/python3.8/site-packages/django/db/models/query.py", line 435, in get
    raise self.model.DoesNotExist(
main.models.Review.DoesNotExist: Review matching query does not exist.
ERROR:django.request:Internal Server Error: /reviews/tilte1-a
Traceback (most recent call last):
  File "/home/andrushens/anime/ISPLabs/lab3-4/my_site/venv/lib/python3.8/site-packages/django/core/handlers/exception.py", line 47, in inner
    response = get_response(request)
  File "/home/andrushens/anime/ISPLabs/lab3-4/my_site/venv/lib/python3.8/site-packages/django/core/handlers/base.py", line 181, in _get_response
    response = wrapped_callback(request, *callback_args, **callback_kwargs)
  File "/home/andrushens/anime/ISPLabs/lab3-4/my_site/venv/lib/python3.8/site-packages/django/views/generic/base.py", line 70, in view
    return self.dispatch(request, *args, **kwargs)
  File "/home/andrushens/anime/ISPLabs/lab3-4/my_site/venv/lib/python3.8/site-packages/django/views/generic/base.py", line 98, in dispatch
    return handler(request, *args, **kwargs)
  File "/home/andrushens/anime/ISPLabs/lab3-4/my_site/main/views.py", line 166, in get
    review = Review.objects.get(slug=slug)
  File "/home/andrushens/anime/ISPLabs/lab3-4/my_site/venv/lib/python3.8/site-packages/django/db/models/manager.py", line 85, in manager_method
    return getattr(self.get_queryset(), name)(*args, **kwargs)
  File "/home/andrushens/anime/ISPLabs/lab3-4/my_site/venv/lib/python3.8/site-packages/django/db/models/query.py", line 435, in get
    raise self.model.DoesNotExist(
main.models.Review.DoesNotExist: Review matching query does not exist.
WARNING:django.request:Not Found: /users/qweqwe
ERROR:django.request:Internal Server Error: /users/232
Traceback (most recent call last):
  File "/home/andrushens/anime/ISPLabs/lab3-4/my_site/venv/lib/python3.8/site-packages/django/core/handlers/exception.py", line 47, in inner
    response = get_response(request)
  File "/home/andrushens/anime/ISPLabs/lab3-4/my_site/venv/lib/python3.8/site-packages/django/core/handlers/base.py", line 181, in _get_response
    response = wrapped_callback(request, *callback_args, **callback_kwargs)
  File "/home/andrushens/anime/ISPLabs/lab3-4/my_site/venv/lib/python3.8/site-packages/django/views/generic/base.py", line 70, in view
    return self.dispatch(request, *args, **kwargs)
  File "/home/andrushens/anime/ISPLabs/lab3-4/my_site/venv/lib/python3.8/site-packages/django/views/generic/base.py", line 98, in dispatch
    return handler(request, *args, **kwargs)
  File "/home/andrushens/anime/ISPLabs/lab3-4/my_site/main/views.py", line 176, in get
    if (Account.objects.get(user_id=pk) is not None):
  File "/home/andrushens/anime/ISPLabs/lab3-4/my_site/venv/lib/python3.8/site-packages/django/db/models/manager.py", line 85, in manager_method
    return getattr(self.get_queryset(), name)(*args, **kwargs)
  File "/home/andrushens/anime/ISPLabs/lab3-4/my_site/venv/lib/python3.8/site-packages/django/db/models/query.py", line 435, in get
    raise self.model.DoesNotExist(
main.models.Account.DoesNotExist: Account matching query does not exist.
WARNING:django.request:Not Found: /static/style.css
WARNING:django.request:Not Found: /static/style.css
INFO:main.views:pudge liked review tilte1
WARNING:django.request:Not Found: /static/style.css
WARNING:django.request:Not Found: /static/style.css
WARNING:django.request:Not Found: /static/style.css
INFO:django.utils.autoreload:/home/andrushens/anime/ISPLabs/lab3-4/my_site/main/views.py changed, reloading.
DEBUG:asyncio:Using selector: EpollSelector
WARNING:django.request:Not Found: /static/style.css
ERROR:django.request:Internal Server Error: /users/1
Traceback (most recent call last):
  File "/home/andrushens/anime/ISPLabs/lab3-4/my_site/venv/lib/python3.8/site-packages/django/core/handlers/exception.py", line 47, in inner
    response = get_response(request)
  File "/home/andrushens/anime/ISPLabs/lab3-4/my_site/venv/lib/python3.8/site-packages/django/core/handlers/base.py", line 181, in _get_response
    response = wrapped_callback(request, *callback_args, **callback_kwargs)
  File "/home/andrushens/anime/ISPLabs/lab3-4/my_site/venv/lib/python3.8/site-packages/django/views/generic/base.py", line 70, in view
    return self.dispatch(request, *args, **kwargs)
  File "/home/andrushens/anime/ISPLabs/lab3-4/my_site/venv/lib/python3.8/site-packages/django/views/generic/base.py", line 98, in dispatch
    return handler(request, *args, **kwargs)
  File "/home/andrushens/anime/ISPLabs/lab3-4/my_site/main/views.py", line 176, in get
    if (Account.objects.get(user_id=pk).count() == 1):
  File "/home/andrushens/anime/ISPLabs/lab3-4/my_site/venv/lib/python3.8/site-packages/django/db/models/manager.py", line 85, in manager_method
    return getattr(self.get_queryset(), name)(*args, **kwargs)
  File "/home/andrushens/anime/ISPLabs/lab3-4/my_site/venv/lib/python3.8/site-packages/django/db/models/query.py", line 435, in get
    raise self.model.DoesNotExist(
main.models.Account.DoesNotExist: Account matching query does not exist.
WARNING:django.request:Not Found: /users/
ERROR:django.request:Internal Server Error: /users/1111
Traceback (most recent call last):
  File "/home/andrushens/anime/ISPLabs/lab3-4/my_site/venv/lib/python3.8/site-packages/django/core/handlers/exception.py", line 47, in inner
    response = get_response(request)
  File "/home/andrushens/anime/ISPLabs/lab3-4/my_site/venv/lib/python3.8/site-packages/django/core/handlers/base.py", line 181, in _get_response
    response = wrapped_callback(request, *callback_args, **callback_kwargs)
  File "/home/andrushens/anime/ISPLabs/lab3-4/my_site/venv/lib/python3.8/site-packages/django/views/generic/base.py", line 70, in view
    return self.dispatch(request, *args, **kwargs)
  File "/home/andrushens/anime/ISPLabs/lab3-4/my_site/venv/lib/python3.8/site-packages/django/views/generic/base.py", line 98, in dispatch
    return handler(request, *args, **kwargs)
  File "/home/andrushens/anime/ISPLabs/lab3-4/my_site/main/views.py", line 176, in get
    if (Account.objects.get(user_id=pk).count() == 1):
  File "/home/andrushens/anime/ISPLabs/lab3-4/my_site/venv/lib/python3.8/site-packages/django/db/models/manager.py", line 85, in manager_method
    return getattr(self.get_queryset(), name)(*args, **kwargs)
  File "/home/andrushens/anime/ISPLabs/lab3-4/my_site/venv/lib/python3.8/site-packages/django/db/models/query.py", line 435, in get
    raise self.model.DoesNotExist(
main.models.Account.DoesNotExist: Account matching query does not exist.
WARNING:django.request:Not Found: /static/style.css
WARNING:django.request:Not Found: /static/style.css
ERROR:django.request:Internal Server Error: /users/19
Traceback (most recent call last):
  File "/home/andrushens/anime/ISPLabs/lab3-4/my_site/venv/lib/python3.8/site-packages/django/core/handlers/exception.py", line 47, in inner
    response = get_response(request)
  File "/home/andrushens/anime/ISPLabs/lab3-4/my_site/venv/lib/python3.8/site-packages/django/core/handlers/base.py", line 181, in _get_response
    response = wrapped_callback(request, *callback_args, **callback_kwargs)
  File "/home/andrushens/anime/ISPLabs/lab3-4/my_site/venv/lib/python3.8/site-packages/django/views/generic/base.py", line 70, in view
    return self.dispatch(request, *args, **kwargs)
  File "/home/andrushens/anime/ISPLabs/lab3-4/my_site/venv/lib/python3.8/site-packages/django/views/generic/base.py", line 98, in dispatch
    return handler(request, *args, **kwargs)
  File "/home/andrushens/anime/ISPLabs/lab3-4/my_site/main/views.py", line 176, in get
    if (Account.objects.get(user_id=pk).count() == 1):
AttributeError: 'Account' object has no attribute 'count'
INFO:django.utils.autoreload:/home/andrushens/anime/ISPLabs/lab3-4/my_site/main/views.py changed, reloading.
DEBUG:asyncio:Using selector: EpollSelector
WARNING:django.request:Not Found: /static/style.css
WARNING:django.request:Not Found: /static/style.css
WARNING:django.request:Not Found: /static/style.css
WARNING:django.request:Not Found: /static/style.css
WARNING:django.request:Not Found: /static/style.css
ERROR:main.views:pudge caused error on creating review
WARNING:django.request:Not Found: /static/style.css
WARNING:django.request:Not Found: /static/style.css
WARNING:django.request:Not Found: /static/style.css
INFO:main.views:pudge created review qqq
WARNING:django.request:Not Found: /static/style.css
WARNING:django.request:Not Found: /static/style.css
WARNING:django.request:Not Found: /static/style.css
WARNING:django.request:Not Found: /static/style.css
INFO:main.views:pudge edited review title1
WARNING:django.request:Not Found: /static/style.css
WARNING:django.request:Not Found: /static/style.css
WARNING:django.request:Not Found: /static/style.css
WARNING:django.request:Not Found: /static/style.css
WARNING:django.request:Not Found: /static/style.css
INFO:main.views:pudge deleted review title1
WARNING:django.request:Not Found: /static/style.css
WARNING:django.request:Not Found: /static/style.css
ERROR:main.views:pudge caused error on creating review
WARNING:django.request:Not Found: /static/style.css
WARNING:django.request:Not Found: /static/style.css
WARNING:django.request:Not Found: /static/style.css
INFO:main.views:pudge created review title 1
WARNING:django.request:Not Found: /static/style.css
INFO:main.views:pudge logged out
WARNING:django.request:Not Found: /static/style.css
INFO:main.views:root logged in
WARNING:django.request:Not Found: /static/style.css
WARNING:django.request:Not Found: /static/style.css
INFO:main.views:root deleted review tilte1
WARNING:django.request:Not Found: /static/style.css
WARNING:django.request:Not Found: /static/style.css
ERROR:main.views:root caused error on creating review
WARNING:django.request:Not Found: /static/style.css
INFO:main.views:root created review title
WARNING:django.request:Not Found: /static/style.css
WARNING:django.request:Not Found: /static/style.css
ERROR:main.views:root caused error on creating review
WARNING:django.request:Not Found: /static/style.css
WARNING:django.request:Not Found: /static/style.css
INFO:django.utils.autoreload:/home/andrushens/anime/ISPLabs/lab3-4/my_site/main/views.py changed, reloading.
DEBUG:asyncio:Using selector: EpollSelector
WARNING:django.request:Not Found: /static/style.css
WARNING:django.request:Not Found: /static/style.css
ERROR:django.request:Internal Server Error: /users/1
Traceback (most recent call last):
  File "/home/andrushens/anime/ISPLabs/lab3-4/my_site/venv/lib/python3.8/site-packages/django/core/handlers/exception.py", line 47, in inner
    response = get_response(request)
  File "/home/andrushens/anime/ISPLabs/lab3-4/my_site/venv/lib/python3.8/site-packages/django/core/handlers/base.py", line 181, in _get_response
    response = wrapped_callback(request, *callback_args, **callback_kwargs)
  File "/home/andrushens/anime/ISPLabs/lab3-4/my_site/venv/lib/python3.8/site-packages/django/views/generic/base.py", line 70, in view
    return self.dispatch(request, *args, **kwargs)
  File "/home/andrushens/anime/ISPLabs/lab3-4/my_site/venv/lib/python3.8/site-packages/django/views/generic/base.py", line 98, in dispatch
    return handler(request, *args, **kwargs)
  File "/home/andrushens/anime/ISPLabs/lab3-4/my_site/main/views.py", line 176, in get
    if (Account.objects.get(user_id=pk) is not None):
  File "/home/andrushens/anime/ISPLabs/lab3-4/my_site/venv/lib/python3.8/site-packages/django/db/models/manager.py", line 85, in manager_method
    return getattr(self.get_queryset(), name)(*args, **kwargs)
  File "/home/andrushens/anime/ISPLabs/lab3-4/my_site/venv/lib/python3.8/site-packages/django/db/models/query.py", line 435, in get
    raise self.model.DoesNotExist(
main.models.Account.DoesNotExist: Account matching query does not exist.
WARNING:django.request:Not Found: /static/style.css
WARNING:django.request:Not Found: /static/style.css
WARNING:django.request:Not Found: /static/style.css
WARNING:django.request:Not Found: /static/style.css
WARNING:django.request:Not Found: /static/style.css
ERROR:main.views:root caused error on updating review
WARNING:django.request:Not Found: /static/style.css
WARNING:django.request:Not Found: /static/style.css
WARNING:django.request:Not Found: /static/style.css
ERROR:main.views:root caused error on creating review
WARNING:django.request:Not Found: /static/style.css
INFO:main.views:root created review fggggh
WARNING:django.request:Not Found: /static/style.css
WARNING:django.request:Not Found: /static/style.css
WARNING:django.request:Not Found: /static/style.css
ERROR:main.views:root caused error on updating review
WARNING:django.request:Not Found: /static/style.css
INFO:main.views:root edited review qwertas1
WARNING:django.request:Not Found: /static/style.css
WARNING:django.request:Not Found: /static/style.css
WARNING:django.request:Not Found: /static/style.css
WARNING:django.request:Not Found: /static/style.css
WARNING:django.request:Not Found: /static/style.css
WARNING:django.request:Not Found: /static/style.css
INFO:main.views:root deleted review qwertas
WARNING:django.request:Not Found: /static/style.css
WARNING:django.request:Not Found: /static/style.css
WARNING:django.request:Not Found: /static/style.css
WARNING:django.request:Not Found: /static/style.css
INFO:main.views:root deleted review qwertas1
WARNING:django.request:Not Found: /static/style.css
WARNING:django.request:Not Found: /static/style.css
INFO:main.views:root liked review title-1
WARNING:django.request:Not Found: /static/style.css
INFO:main.views:root disliked review title-1
WARNING:django.request:Not Found: /static/style.css
INFO:main.views:root liked review title-1
WARNING:django.request:Not Found: /static/style.css
WARNING:django.request:Not Found: /static/style.css
WARNING:django.request:Not Found: /static/style.css
WARNING:django.request:Not Found: /static/style.css
WARNING:django.request:Not Found: /static/style.css
WARNING:django.request:Not Found: /static/style.css
ERROR:django.security.DisallowedHost:Invalid HTTP_HOST header: '0.0.0.0:8000'. You may need to add '0.0.0.0' to ALLOWED_HOSTS.
WARNING:django.request:Bad Request: /users
ERROR:django.security.DisallowedHost:Invalid HTTP_HOST header: '0.0.0.0:8000'. You may need to add '0.0.0.0' to ALLOWED_HOSTS.
WARNING:django.request:Bad Request: /users/19
ERROR:django.security.DisallowedHost:Invalid HTTP_HOST header: '0.0.0.0:8000'. You may need to add '0.0.0.0' to ALLOWED_HOSTS.
WARNING:django.request:Bad Request: /reviews/title
ERROR:django.request:Internal Server Error: /reviews/w/like
Traceback (most recent call last):
  File "/home/andrushens/anime/ISPLabs/lab3-4/my_site/venv/lib/python3.8/site-packages/django/core/handlers/exception.py", line 47, in inner
    response = get_response(request)
  File "/home/andrushens/anime/ISPLabs/lab3-4/my_site/venv/lib/python3.8/site-packages/django/core/handlers/base.py", line 181, in _get_response
    response = wrapped_callback(request, *callback_args, **callback_kwargs)
  File "/home/andrushens/anime/ISPLabs/lab3-4/my_site/venv/lib/python3.8/site-packages/django/contrib/auth/decorators.py", line 21, in _wrapped_view
    return view_func(request, *args, **kwargs)
  File "/home/andrushens/anime/ISPLabs/lab3-4/my_site/main/views.py", line 144, in like_review
    if request.user == Review.objects.filter(slug=slug).first().author.user:
AttributeError: 'NoneType' object has no attribute 'author'
WARNING:django.request:Not Found: /static/style.css
WARNING:django.request:Not Found: /static/style.css
ERROR:django.security.DisallowedHost:Invalid HTTP_HOST header: '0.0.0.0:8000'. You may need to add '0.0.0.0' to ALLOWED_HOSTS.
WARNING:django.request:Bad Request: /reviews/title
ERROR:django.security.DisallowedHost:Invalid HTTP_HOST header: '0.0.0.0:8000'. You may need to add '0.0.0.0' to ALLOWED_HOSTS.
WARNING:django.request:Bad Request: /favicon.ico
INFO:django.utils.autoreload:/home/andrushens/anime/ISPLabs/lab3-4/my_site/main/views.py changed, reloading.
DEBUG:asyncio:Using selector: EpollSelector
DEBUG:asyncio:Using selector: EpollSelector
DEBUG:asyncio:Using selector: EpollSelector
DEBUG:asyncio:Using selector: EpollSelector
DEBUG:asyncio:Using selector: EpollSelector
DEBUG:asyncio:Using selector: EpollSelector
DEBUG:asyncio:Using selector: EpollSelector
DEBUG:asyncio:Using selector: EpollSelector
DEBUG:asyncio:Using selector: EpollSelector
DEBUG:asyncio:Using selector: EpollSelector
DEBUG:asyncio:Using selector: EpollSelector
DEBUG:asyncio:Using selector: EpollSelector
